INFO 2020-01-17 16:46:45,430 views Quiz of question 10 started.
INFO 2020-01-17 16:47:55,631 autoreload Watching for file changes with StatReloader
INFO 2020-01-17 16:48:04,237 autoreload /home/akg/research/shared/webteam/randomAttendance/attendance/settings.py changed, reloading.
INFO 2020-01-17 17:01:38,381 views Quiz for Question 10 is stopped.
INFO 2020-01-17 17:02:00,561 views Quiz of question 10 started.
INFO 2020-01-17 17:32:20,720 views Quiz for Question 10 is stopped.
INFO 2020-01-17 17:34:33,484 views Quiz of question 10 started.
INFO 2020-01-17 17:34:35,391 views Quiz for Question 10 is stopped.
INFO 2020-01-17 18:53:16,721 views Quiz of question 10 started.
INFO 2020-01-17 18:53:19,628 views Quiz for Question 10 is stopped.
INFO 2020-01-17 19:46:23,935 views Question 12 created.
INFO 2020-01-17 21:24:19,749 views Quiz of question 10 started.
ERROR 2020-01-17 21:24:25,526 log Internal Server Error: /answer/263/
Traceback (most recent call last):
  File "/home/akg/.local/lib/python3.6/site-packages/django/core/handlers/exception.py", line 34, in inner
    response = get_response(request)
  File "/home/akg/.local/lib/python3.6/site-packages/django/core/handlers/base.py", line 115, in _get_response
    response = self.process_exception_by_middleware(e, request)
  File "/home/akg/.local/lib/python3.6/site-packages/django/core/handlers/base.py", line 113, in _get_response
    response = wrapped_callback(request, *callback_args, **callback_kwargs)
  File "/home/akg/.local/lib/python3.6/site-packages/django/views/generic/base.py", line 71, in view
    return self.dispatch(request, *args, **kwargs)
  File "/home/akg/.local/lib/python3.6/site-packages/django/views/generic/base.py", line 97, in dispatch
    return handler(request, *args, **kwargs)
  File "/home/akg/.local/lib/python3.6/site-packages/django/views/generic/edit.py", line 190, in get
    return super().get(request, *args, **kwargs)
  File "/home/akg/.local/lib/python3.6/site-packages/django/views/generic/edit.py", line 133, in get
    return self.render_to_response(self.get_context_data())
  File "/home/akg/research/shared/webteam/randomAttendance/studenthome/views.py", line 470, in get_context_data
    context[ "q_ans1" ] = get_q_ans( q, sa.op1 )
UnboundLocalError: local variable 'q' referenced before assignment
ERROR 2020-01-17 21:24:25,526 basehttp "GET /answer/263/ HTTP/1.1" 500 93824
INFO 2020-01-17 21:25:46,161 views Quiz for Question 10 is stopped.
ERROR 2020-01-17 21:26:17,271 log Internal Server Error: /editq/10/
Traceback (most recent call last):
  File "/home/akg/.local/lib/python3.6/site-packages/django/core/handlers/exception.py", line 34, in inner
    response = get_response(request)
  File "/home/akg/.local/lib/python3.6/site-packages/django/core/handlers/base.py", line 115, in _get_response
    response = self.process_exception_by_middleware(e, request)
  File "/home/akg/.local/lib/python3.6/site-packages/django/core/handlers/base.py", line 113, in _get_response
    response = wrapped_callback(request, *callback_args, **callback_kwargs)
  File "/home/akg/.local/lib/python3.6/site-packages/django/views/generic/base.py", line 71, in view
    return self.dispatch(request, *args, **kwargs)
  File "/home/akg/.local/lib/python3.6/site-packages/django/views/generic/base.py", line 97, in dispatch
    return handler(request, *args, **kwargs)
  File "/home/akg/.local/lib/python3.6/site-packages/django/views/generic/edit.py", line 194, in post
    return super().post(request, *args, **kwargs)
  File "/home/akg/.local/lib/python3.6/site-packages/django/views/generic/edit.py", line 142, in post
    return self.form_valid(form)
  File "/home/akg/.local/lib/python3.6/site-packages/django/views/generic/edit.py", line 126, in form_valid
    return super().form_valid(form)
  File "/home/akg/.local/lib/python3.6/site-packages/django/views/generic/edit.py", line 57, in form_valid
    return HttpResponseRedirect(self.get_success_url())
  File "/home/akg/research/shared/webteam/randomAttendance/studenthome/views.py", line 321, in get_success_url
    logq.info( 'Question ' + str(pk_url_kwarg) + ' edited.' )
NameError: name 'pk_url_kwarg' is not defined
ERROR 2020-01-17 21:26:17,272 basehttp "POST /editq/10/ HTTP/1.1" 500 104504
INFO 2020-01-17 21:28:17,742 views Question 10 edited.
ERROR 2020-02-04 22:40:27,181 log Internal Server Error: /all/
Traceback (most recent call last):
  File "/home/akg/.local/lib/python3.6/site-packages/django/core/handlers/exception.py", line 34, in inner
    response = get_response(request)
  File "/home/akg/.local/lib/python3.6/site-packages/django/core/handlers/base.py", line 115, in _get_response
    response = self.process_exception_by_middleware(e, request)
  File "/home/akg/.local/lib/python3.6/site-packages/django/core/handlers/base.py", line 113, in _get_response
    response = wrapped_callback(request, *callback_args, **callback_kwargs)
  File "/home/akg/research/shared/webteam/randomAttendance/studenthome/views.py", line 546, in all_status
    attend_count_map[dt] = attend_count_map[dt] + 1
KeyError: '01-17'
ERROR 2020-02-04 22:40:27,182 basehttp "GET /all/ HTTP/1.1" 500 76364
ERROR 2020-03-10 23:42:08,174 log Internal Server Error: /viewq/9/
Traceback (most recent call last):
  File "/home/akg/.local/lib/python3.6/site-packages/django/template/backends/django.py", line 61, in render
    return self.template.render(context)
  File "/home/akg/.local/lib/python3.6/site-packages/django/template/base.py", line 171, in render
    return self._render(context)
  File "/home/akg/.local/lib/python3.6/site-packages/django/template/base.py", line 163, in _render
    return self.nodelist.render(context)
  File "/home/akg/.local/lib/python3.6/site-packages/django/template/base.py", line 937, in render
    bit = node.render_annotated(context)
  File "/home/akg/.local/lib/python3.6/site-packages/django/template/base.py", line 904, in render_annotated
    return self.render(context)
  File "/home/akg/.local/lib/python3.6/site-packages/django/template/loader_tags.py", line 150, in render
    return compiled_parent._render(context)
  File "/home/akg/.local/lib/python3.6/site-packages/django/template/base.py", line 163, in _render
    return self.nodelist.render(context)
  File "/home/akg/.local/lib/python3.6/site-packages/django/template/base.py", line 937, in render
    bit = node.render_annotated(context)
  File "/home/akg/.local/lib/python3.6/site-packages/django/template/base.py", line 904, in render_annotated
    return self.render(context)
  File "/home/akg/.local/lib/python3.6/site-packages/django/template/loader_tags.py", line 62, in render
    result = block.nodelist.render(context)
  File "/home/akg/.local/lib/python3.6/site-packages/django/template/base.py", line 937, in render
    bit = node.render_annotated(context)
  File "/home/akg/.local/lib/python3.6/site-packages/django/template/base.py", line 904, in render_annotated
    return self.render(context)
  File "/home/akg/.local/lib/python3.6/site-packages/django/template/loader_tags.py", line 176, in render
    template = context.template.engine.get_template(template_name)
  File "/home/akg/.local/lib/python3.6/site-packages/django/template/engine.py", line 143, in get_template
    template, origin = self.find_template(template_name)
  File "/home/akg/.local/lib/python3.6/site-packages/django/template/engine.py", line 129, in find_template
    raise TemplateDoesNotExist(name, tried=tried)
django.template.exceptions.TemplateDoesNotExist: snippets/list.html

The above exception was the direct cause of the following exception:

Traceback (most recent call last):
  File "/home/akg/.local/lib/python3.6/site-packages/django/core/handlers/exception.py", line 34, in inner
    response = get_response(request)
  File "/home/akg/.local/lib/python3.6/site-packages/django/core/handlers/base.py", line 115, in _get_response
    response = self.process_exception_by_middleware(e, request)
  File "/home/akg/.local/lib/python3.6/site-packages/django/core/handlers/base.py", line 113, in _get_response
    response = wrapped_callback(request, *callback_args, **callback_kwargs)
  File "/home/akg/research/shared/webteam/randomAttendance/studenthome/views.py", line 356, in viewq
    return render( request, 'studenthome/viewq.html', context.flatten() )
  File "/home/akg/.local/lib/python3.6/site-packages/django/shortcuts.py", line 36, in render
    content = loader.render_to_string(template_name, context, request, using=using)
  File "/home/akg/.local/lib/python3.6/site-packages/django/template/loader.py", line 62, in render_to_string
    return template.render(context, request)
  File "/home/akg/.local/lib/python3.6/site-packages/django/template/backends/django.py", line 63, in render
    reraise(exc, self.backend)
  File "/home/akg/.local/lib/python3.6/site-packages/django/template/backends/django.py", line 84, in reraise
    raise new from exc
django.template.exceptions.TemplateDoesNotExist: snippets/list.html
ERROR 2020-03-10 23:42:08,201 basehttp "GET /viewq/9/ HTTP/1.1" 500 184520
ERROR 2020-03-11 00:04:20,263 log Internal Server Error: /viewq/9/
Traceback (most recent call last):
  File "/home/akg/.local/lib/python3.6/site-packages/django/core/handlers/exception.py", line 34, in inner
    response = get_response(request)
  File "/home/akg/.local/lib/python3.6/site-packages/django/core/handlers/base.py", line 115, in _get_response
    response = self.process_exception_by_middleware(e, request)
  File "/home/akg/.local/lib/python3.6/site-packages/django/core/handlers/base.py", line 113, in _get_response
    response = wrapped_callback(request, *callback_args, **callback_kwargs)
  File "/home/akg/research/shared/webteam/randomAttendance/studenthome/views.py", line 356, in viewq
    return render( request, 'studenthome/viewq.html', context.flatten() )
  File "/home/akg/.local/lib/python3.6/site-packages/django/shortcuts.py", line 36, in render
    content = loader.render_to_string(template_name, context, request, using=using)
  File "/home/akg/.local/lib/python3.6/site-packages/django/template/loader.py", line 61, in render_to_string
    template = get_template(template_name, using=using)
  File "/home/akg/.local/lib/python3.6/site-packages/django/template/loader.py", line 15, in get_template
    return engine.get_template(template_name)
  File "/home/akg/.local/lib/python3.6/site-packages/django/template/backends/django.py", line 34, in get_template
    return Template(self.engine.get_template(template_name), self)
  File "/home/akg/.local/lib/python3.6/site-packages/django/template/engine.py", line 143, in get_template
    template, origin = self.find_template(template_name)
  File "/home/akg/.local/lib/python3.6/site-packages/django/template/engine.py", line 125, in find_template
    template = loader.get_template(name, skip=skip)
  File "/home/akg/.local/lib/python3.6/site-packages/django/template/loaders/base.py", line 30, in get_template
    contents, origin, origin.template_name, self.engine,
  File "/home/akg/.local/lib/python3.6/site-packages/django/template/base.py", line 156, in __init__
    self.nodelist = self.compile_nodelist()
  File "/home/akg/.local/lib/python3.6/site-packages/django/template/base.py", line 194, in compile_nodelist
    return parser.parse()
  File "/home/akg/.local/lib/python3.6/site-packages/django/template/base.py", line 478, in parse
    raise self.error(token, e)
  File "/home/akg/.local/lib/python3.6/site-packages/django/template/base.py", line 476, in parse
    compiled_result = compile_func(self, token)
  File "/home/akg/.local/lib/python3.6/site-packages/django/template/loader_tags.py", line 266, in do_extends
    nodelist = parser.parse()
  File "/home/akg/.local/lib/python3.6/site-packages/django/template/base.py", line 478, in parse
    raise self.error(token, e)
  File "/home/akg/.local/lib/python3.6/site-packages/django/template/base.py", line 476, in parse
    compiled_result = compile_func(self, token)
  File "/home/akg/.local/lib/python3.6/site-packages/django/template/loader_tags.py", line 209, in do_block
    nodelist = parser.parse(('endblock',))
  File "/home/akg/.local/lib/python3.6/site-packages/django/template/base.py", line 478, in parse
    raise self.error(token, e)
  File "/home/akg/.local/lib/python3.6/site-packages/django/template/base.py", line 476, in parse
    compiled_result = compile_func(self, token)
  File "/home/akg/.local/lib/python3.6/site-packages/django/template/loader_tags.py", line 311, in do_include
    (bits[0], option))
django.template.exceptions.TemplateSyntaxError: Unknown argument for 'include' tag: 'qans='.
ERROR 2020-03-11 00:04:20,264 basehttp "GET /viewq/9/ HTTP/1.1" 500 173983
INFO 2020-03-11 00:10:44,315 views Quiz of question 10 started.
